[ 2025-05-23 13:28:17,691 ] 97 werkzeug - INFO - [31m[1mWARNING: This is a development server. Do not use it in a production deployment. Use a production WSGI server instead.[0m
 * Running on all addresses (0.0.0.0)
 * Running on http://127.0.0.1:5000
 * Running on http://10.0.0.38:5000
[ 2025-05-23 13:28:17,691 ] 97 werkzeug - INFO - [33mPress CTRL+C to quit[0m
[ 2025-05-23 13:30:53,555 ] 97 werkzeug - INFO - 127.0.0.1 - - [23/May/2025 13:30:53] "GET / HTTP/1.1" 200 -
[ 2025-05-23 13:32:11,550 ] 97 werkzeug - INFO - 127.0.0.1 - - [23/May/2025 13:32:11] "GET /predictdata HTTP/1.1" 200 -
[ 2025-05-23 13:32:32,725 ] 875 app - ERROR - Exception on /predictdata [POST]
Traceback (most recent call last):
  File "/Users/pradyumna/Downloads/mlproject/src/pipeline/predict_pipeline.py", line 13, in predict
    model_path=os.path.join("artifacts","model.pkl")
               ^^
NameError: name 'os' is not defined. Did you forget to import 'os'?

During handling of the above exception, another exception occurred:

Traceback (most recent call last):
  File "/Users/pradyumna/Desktop/Data Science/venv/lib/python3.13/site-packages/flask/app.py", line 1511, in wsgi_app
    response = self.full_dispatch_request()
  File "/Users/pradyumna/Desktop/Data Science/venv/lib/python3.13/site-packages/flask/app.py", line 919, in full_dispatch_request
    rv = self.handle_user_exception(e)
  File "/Users/pradyumna/Desktop/Data Science/venv/lib/python3.13/site-packages/flask/app.py", line 917, in full_dispatch_request
    rv = self.dispatch_request()
  File "/Users/pradyumna/Desktop/Data Science/venv/lib/python3.13/site-packages/flask/app.py", line 902, in dispatch_request
    return self.ensure_sync(self.view_functions[rule.endpoint])(**view_args)  # type: ignore[no-any-return]
           ~~~~~~~~~~~~~~~~~~~~~~~~~~~~~~~~~~~~~~~~~~~~~~~~~~~~^^^^^^^^^^^^^
  File "/Users/pradyumna/Downloads/mlproject/app.py", line 39, in predict_datapoint
    results=predict_pipeline.predict(pred_df)
  File "/Users/pradyumna/Downloads/mlproject/src/pipeline/predict_pipeline.py", line 24, in predict
    raise CustomException(e,sys)
src.exception.CustomException: Error occured in python script name [/Users/pradyumna/Downloads/mlproject/src/pipeline/predict_pipeline.py] line number [13] error message[name 'os' is not defined]
[ 2025-05-23 13:32:32,730 ] 97 werkzeug - INFO - 127.0.0.1 - - [23/May/2025 13:32:32] "[35m[1mPOST /predictdata HTTP/1.1[0m" 500 -
[ 2025-05-23 13:34:05,694 ] 875 app - ERROR - Exception on /predictdata [POST]
Traceback (most recent call last):
  File "/Users/pradyumna/Downloads/mlproject/src/pipeline/predict_pipeline.py", line 13, in predict
    model_path=os.path.join("artifacts","model.pkl")
               ^^
NameError: name 'os' is not defined. Did you forget to import 'os'?

During handling of the above exception, another exception occurred:

Traceback (most recent call last):
  File "/Users/pradyumna/Desktop/Data Science/venv/lib/python3.13/site-packages/flask/app.py", line 1511, in wsgi_app
    response = self.full_dispatch_request()
  File "/Users/pradyumna/Desktop/Data Science/venv/lib/python3.13/site-packages/flask/app.py", line 919, in full_dispatch_request
    rv = self.handle_user_exception(e)
  File "/Users/pradyumna/Desktop/Data Science/venv/lib/python3.13/site-packages/flask/app.py", line 917, in full_dispatch_request
    rv = self.dispatch_request()
  File "/Users/pradyumna/Desktop/Data Science/venv/lib/python3.13/site-packages/flask/app.py", line 902, in dispatch_request
    return self.ensure_sync(self.view_functions[rule.endpoint])(**view_args)  # type: ignore[no-any-return]
           ~~~~~~~~~~~~~~~~~~~~~~~~~~~~~~~~~~~~~~~~~~~~~~~~~~~~^^^^^^^^^^^^^
  File "/Users/pradyumna/Downloads/mlproject/app.py", line 39, in predict_datapoint
    results=predict_pipeline.predict(pred_df)
  File "/Users/pradyumna/Downloads/mlproject/src/pipeline/predict_pipeline.py", line 24, in predict
    raise CustomException(e,sys)
src.exception.CustomException: Error occured in python script name [/Users/pradyumna/Downloads/mlproject/src/pipeline/predict_pipeline.py] line number [13] error message[name 'os' is not defined]
[ 2025-05-23 13:34:05,697 ] 97 werkzeug - INFO - 127.0.0.1 - - [23/May/2025 13:34:05] "[35m[1mPOST /predictdata HTTP/1.1[0m" 500 -
